<?xml version="1.0" ?>
<sdf version="1.4">
<model name="V2Exoskeleton">

  <link name="pelvis">
    <pose>0.025 0.8 0.22 0 0 0</pose>
    <visual name="pelvis_visual">
      <pose>-0.025 -0.8 -0.22 1.5707963267949 0 1.5707963267949</pose>
      <geometry>
        <mesh>
					<uri>file://meshes/pelvis.stl</uri>
				</mesh>
      </geometry>
    </visual>
    <inertial>
      <pose>-0.3834 -0.8 0.6729 0 0 0</pose>
      <mass>4.4169343065694</mass>
      <inertia>
        <ixx>0.521</ixx>
        <iyy>0.184</iyy>
        <izz>0.384</izz>
        <iyz>-0.23</iyz>
        <ixz>0</ixz>
        <ixy>0</ixy>
      </inertia>
    </inertial>
    <sensor name="imu_sensor_at_pelvis_frame" type="imu">
      <always_on>1</always_on>
      <update_rate>1000</update_rate>
      <imu>
        <noise>
          <accel>
            <bias_mean>0.1</bias_mean>
            <bias_stddev>0.001</bias_stddev>
            <mean>0</mean>
            <stddev>0.017</stddev>
          </accel>
          <rate>
            <bias_mean>7.5e-06</bias_mean>
            <bias_stddev>8e-07</bias_stddev>
            <mean>0</mean>
            <stddev>0.0001</stddev>
          </rate>
          <type>gaussian</type>
        </noise>
      </imu>
      <pose>0 0 0 0 0 0</pose>
    </sensor>
    <sensor name="imu_sensor_at_imu_frame" type="imu">
      <always_on>1</always_on>
      <update_rate>1000</update_rate>
      <imu>
        <noise>
          <accel>
            <bias_mean>0.1</bias_mean>
            <bias_stddev>0.001</bias_stddev>
            <mean>0</mean>
            <stddev>0.017</stddev>
          </accel>
          <rate>
            <bias_mean>7.5e-06</bias_mean>
            <bias_stddev>8e-07</bias_stddev>
            <mean>0</mean>
            <stddev>0.0001</stddev>
          </rate>
          <type>gaussian</type>
        </noise>
      </imu>
      <pose>0 0 0 0 0 0</pose>
    </sensor>
  </link>


  <link name="l_uleg">
    <pose>0 0.0332 0.30716 0 0 0</pose>
    <visual name="l_thigh_visual">
      <pose>-0 -0.0332 -0.30716 0 0 0</pose>
      <geometry>
        <mesh>
					<uri>file://meshes/left_thigh.stl</uri>
				</mesh>
      </geometry>
    </visual>
    <inertial>
      <pose>-0.148639 0.1878 0.257032 0 0 0</pose>
      <mass>3.6007616629642</mass>
      <inertia>
        <ixx>0.3834</ixx>
        <iyy>0.013</iyy>
        <izz>0.3746</izz>
        <iyz>-0.0434</iyz>
        <ixz>0.0001</ixz>
        <ixy>0</ixy>
      </inertia>
    </inertial>
  </link>

  <link name="r_uleg">
    <pose>0.02 -0.0625 -0.061 0 0 0</pose>
    <visual name="r_thigh_visual">
      <pose>-0.02 0.0625 0.061 -1.5707963267949 0 -1.5707963267949</pose>
      <geometry>
        <mesh>
					<uri>file://meshes/right_thigh.stl</uri>
				</mesh>
      </geometry>
    </visual>
    <inertial>
      <pose>-0.168639 -0.1585 0.625192 0 0 0</pose>
      <mass>3.6007616629642</mass>
      <inertia>
        <ixx>0.3834</ixx>
        <iyy>0.013</iyy>
        <izz>0.3746</izz>
        <iyz>-0.0434</iyz>
        <ixz>0.0001</ixz>
        <ixy>0</ixy>
      </inertia>
    </inertial>
  </link>


  <link name="l_lleg">
    <pose>-0.0975 0.9975 0.5025 0 0 0</pose>
    <visual name="l_shin_visual">
      <pose>0.0975 -0.9975 -0.5025 1.5707963267949 0 1.5707963267949</pose>
      <geometry>
        <mesh>
					<uri>file://meshes/left_shin.stl</uri>
				</mesh>
      </geometry>
    </visual>
    <inertial>
      <pose>-0.188955 -0.8097 -0.469365 0 0 0</pose>
      <mass>3.1555274833386</mass>
      <inertia>
        <ixx>0.0775</ixx>
        <iyy>0.009</iyy>
        <izz>0.0711</izz>
        <iyz>-0.0085</iyz>
        <ixz>0.0004</ixz>
        <ixy>-0.0021</ixy>
      </inertia>
    </inertial>
  </link>

  <link name="r_lleg">
    <pose>-0.0975 0.6135 0.5025 0 0 0</pose>
    <visual name="r_shin_visual">
      <pose>0.0975 -0.6135 -0.5025 1.5707963267949 0 1.5707963267949</pose>
      <geometry>
        <mesh>
					<uri>file://meshes/right_shin.stl</uri>
				</mesh>
      </geometry>
    </visual>
    <inertial>
      <pose>-0.188955 -0.8013 -0.469365 0 0 0</pose>
      <mass>3.1555274833386</mass>
      <inertia>
        <ixx>0.0775</ixx>
        <iyy>0.009</iyy>
        <izz>0.0711</izz>
        <iyz>-0.0085</iyz>
        <ixz>0.0004</ixz>
        <ixy>-0.0021</ixy>
      </inertia>
    </inertial>
  </link>


  <link name="l_foot">
    <pose>-0.0685 0.1725 0.086 0 0 0</pose>
    <visual name="l_foot_visual">
      <pose>0.0685 -0.1725 -0.086 1.5707963267949 0 1.5707963267949</pose>
      <geometry>
        <mesh>
					<uri>file://meshes/left_foot.stl</uri>
				</mesh>
      </geometry>
    </visual>
    <inertial>
      <pose>-0.1102431 -0.056064 -0.248288 0 0 0</pose>
      <mass>0.49010367079234</mass>
      <inertia>
        <ixx>0.4259</ixx>
        <iyy>0.01108</iyy>
        <izz>0.42668</izz>
        <iyz>-0.02838</iyz>
        <ixz>0.00276</ixz>
        <ixy>-0.04594</ixy>
      </inertia>
    </inertial>
  </link>

  <link name="r_foot">
    <pose>-0.1225 0.6325 0.086 0 0 0</pose>
    <visual name="r_foot_visual">
      <pose>0.1225 -0.6325 -0.086 1.5707963267949 0 1.5707963267949</pose>
      <geometry>
        <mesh>
					<uri>file://meshes/right_foot.stl</uri>
				</mesh>
      </geometry>
    </visual>
    <inertial>
      <pose>-0.0562431 -0.748936 -0.248288 0 0 0</pose>
      <mass>0.49010367079234</mass>
      <inertia>
        <ixx>0.4259</ixx>
        <iyy>0.01108</iyy>
        <izz>0.42668</izz>
        <iyz>-0.02838</iyz>
        <ixz>0.00276</ixz>
        <ixy>-0.04594</ixy>
      </inertia>
    </inertial>
  </link>

  <joint name="l_leg_hpy" type="revolute">
    <pose>-0.22235 0.1878 0.455232 0 0 0</pose>
    <parent>
      pelvis
    </parent>
    <child>
      l_uleg
    </child>
    <axis>
      <xyz>0 1 0</xyz>
      <limit>
        <lower>-2.0943951023932</lower>
        <upper>0.5235987755983</upper>
        <effort>150</effort>
        <velocity>12</velocity>
      </limit>
      <dynamics>
        <damping>1.0</damping>
        <friction>0</friction>
      </dynamics>
    </axis>
    <physics>
      <ode>
        <cfm_damping>1</cfm_damping>
      </ode>
    </physics>
  </joint>

  <joint name="r_leg_hpy" type="revolute">
    <pose>-0.24235 -0.1585 0.823392 0 0 0</pose>
    <parent>
      pelvis
    </parent>
    <child>
      r_uleg
    </child>
    <axis>
      <xyz>0 1 0</xyz>
      <limit>
        <lower>-2.0943951023932</lower>
        <upper>0.5235987755983</upper>
        <effort>150</effort>
        <velocity>12</velocity>
      </limit>
      <dynamics>
        <damping>1.0</damping>
        <friction>0</friction>
      </dynamics>
    </axis>
    <physics>
      <ode>
        <cfm_damping>1</cfm_damping>
      </ode>
    </physics>
  </joint>

  <joint name="l_leg_kny" type="revolute">
    <pose>-0.188955 -0.7765 -0.162205 0 0 0</pose>
    <parent>
      l_uleg
    </parent>
    <child>
      l_lleg
    </child>
    <axis>
      <xyz>0 1 0</xyz>
      <limit>
        <lower>0</lower>
        <upper>2.3561944901923</upper>
        <effort>150</effort>
        <velocity>12</velocity>
      </limit>
      <dynamics>
        <damping>1.0</damping>
        <friction>0</friction>
      </dynamics>
    </axis>
    <physics>
      <ode>
        <cfm_damping>1</cfm_damping>
      </ode>
    </physics>
  </joint>

  <joint name="r_leg_kny" type="revolute">
    <pose>-0.188955 -0.8345 -0.162205 0 0 0</pose>
    <parent>
      r_uleg
    </parent>
    <child>
      r_lleg
    </child>
    <axis>
      <xyz>0 1 0</xyz>
      <limit>
        <lower>0</lower>
        <upper>2.3561944901923</upper>
        <effort>150</effort>
        <velocity>12</velocity>
      </limit>
      <dynamics>
        <damping>1.0</damping>
        <friction>0</friction>
      </dynamics>
    </axis>
    <physics>
      <ode>
        <cfm_damping>1</cfm_damping>
      </ode>
    </physics>
  </joint>

  <joint name="l_leg_aky" type="revolute">
    <parent>
      l_lleg
    </parent>
    <child>
      l_foot
    </child>
    <axis>
      <xyz>0 1 0</xyz>
      <limit>
        <lower>-0.95993108859688</lower>
        <upper>0.61086523819802</upper>
        <effort>150</effort>
        <velocity>12</velocity>
      </limit>
      <dynamics>
        <damping>1.0</damping>
        <friction>0</friction>
      </dynamics>
    </axis>
    <physics>
      <ode>
        <cfm_damping>1</cfm_damping>
      </ode>
    </physics>
  </joint>

  <joint name="r_leg_aky" type="revolute">
    <parent>
      r_lleg
    </parent>
    <child>
      r_foot
    </child>
    <axis>
      <xyz>0 1 0</xyz>
      <limit>
        <lower>-0.95993108859688</lower>
        <upper>0.61086523819802</upper>
        <effort>150</effort>
        <velocity>12</velocity>
      </limit>
      <dynamics>
        <damping>1.0</damping>
        <friction>0</friction>
      </dynamics>
    </axis>
    <physics>
      <ode>
        <cfm_damping>1</cfm_damping>
      </ode>
    </physics>
  </joint>

</model>
</sdf>


