<?xml version="1.0"?>
<robot name="V2Exoskeleton" xmlns:xacro="http://www.ros.org/wiki/xacro">

  <link name="pelvis">
    <origin xyz="${pelvis_frame.X} ${pelvis_frame.Y} ${pelvis_frame.Z}" />
    <visual name="pelvis_visual">
      <origin xyz="${pelvis.origin}" />
      <geometry>
        ${pelvis.geometry}
      </geometry>
    </visual>
    <inertial>
      <origin xyz="${pelvis.Xcbar - pelvis_frame.X} ${pelvis.Ycbar - pelvis_frame.Y} ${pelvis.Zcbar - pelvis_frame.Z}" />
      <mass value="4.4169343065694" />
      <inertia ixx="0.521" iyy="0.184" izz="0.384" iyz="-0.23" ixz="0" ixy="0" />
    </inertial>
  </link>

  <link name="l_uleg">
    <visual name="l_uleg_visual">
      <origin xyz="0.22235 -0.221 -0.762392" />
      <geometry>
        <mesh filename="package://escher_description/meshes/l_thigh.stl" scale=".001 .001 .001" />
      </geometry>
    </visual>
    <inertial>
      <origin xyz="0.073711 0 -0.1982" />
      <mass value="3.6007616629642" />
      <inertia ixx="0.3834" iyy="0.013" izz="0.3746" iyz="-0.0434" ixz="0.0001" ixy="0" />
    </inertial>
  </link>

  <link name="r_uleg">
    <visual name="r_uleg_visual">
      <origin xyz="0.22235 0.221 -0.762392" />
      <geometry>
        <mesh filename="package://escher_description/meshes/r_thigh.stl" scale=".001 .001 .001" />
      </geometry>
    </visual>
    <inertial>
      <origin xyz="0.073711 0 -0.1982" />
      <mass value="3.6007616629642" />
      <inertia ixx="0.3834" iyy="0.013" izz="0.3746" iyz="-0.0434" ixz="0.0001" ixy="0" />
    </inertial>
  </link>

  <link name="l_lleg">
    <visual name="l_lleg_visual">
      <origin xyz="0.286455 -0.221 -0.340295" />
      <geometry>
        <mesh filename="package://escher_description/meshes/l_shin.stl" scale=".001 .001 .001" />
      </geometry>
    </visual>
    <inertial>
      <origin xyz="0 -0.0332 -0.30716" />
      <mass value="3.1555274833386" />
      <inertia ixx="0.0775" iyy="0.009" izz="0.0711" iyz="-0.0085" ixz="0.0004" ixy="-0.0021" />
    </inertial>
  </link>

  <link name="r_lleg">
    <visual name="r_lleg_visual">
      <origin xyz="0.286455 0.221 -0.340295" />
      <geometry>
        <mesh filename="package://escher_description/meshes/r_shin.stl" scale=".001 .001 .001" />
      </geometry>
    </visual>
    <inertial>
      <origin xyz="0 0.0332 -0.30716" />
      <mass value="3.1555274833386" />
      <inertia ixx="0.0775" iyy="0.009" izz="0.0711" iyz="-0.0085" ixz="0.0004" ixy="-0.0021" />
    </inertial>
  </link>


  <link name="l_foot">
    <visual name="l_foot_visual">
      <origin xyz="0.236749 -0.186 0.0787674" />
      <geometry>
        <mesh filename="package://escher_description/meshes/l_foot.stl" scale=".001 .001 .001" />
      </geometry>
    </visual>
    <inertial>
      <origin xyz="0.0580059 -0.069564 -0.0835206" />
      <mass value="0.49010367079234" />
      <inertia ixx="0.4259" iyy="0.01108" izz="0.42668" iyz="-0.02838" ixz="0.00276" ixy="-0.04594" />
    </inertial>
  </link>

  <link name="r_foot">
    <visual name="r_foot_visual">
      <origin xyz="0.236749 0.186 0.0787674" />
      <geometry>
        <mesh filename="package://escher_description/meshes/r_foot.stl" scale=".001 .001 .001" />
      </geometry>
    </visual>
    <inertial>
      <origin xyz="0.0580059 0.069564 -0.0835206" />
      <mass value="0.49010367079234" />
      <inertia ixx="0.4259" iyy="0.01108" izz="0.42668" iyz="-0.02838" ixz="0.00276" ixy="-0.04594" />
    </inertial>
  </link>

  <joint name="l_leg_hpy" type="revolute">
    <origin xyz="0 0 0" />
    <parent link="pelvis" />
    <child link="l_uleg" />
    <axis xyz="0 1 0" />
    <limit lower="-2.0943951023932" upper="0.5235987755983" effort="150" velocity="1.6" />
    <dynamics damping="1.0" friction="0" />
  </joint>

  <joint name="r_leg_hpy" type="revolute">
    <origin xyz="0 0 0" />
    <parent link="pelvis" />
    <child link="r_uleg" />
    <axis xyz="0 1 0" />
    <limit lower="-2.0943951023932" upper="0.5235987755983" effort="150" velocity="1.6" />
    <dynamics damping="1.0" friction="0" />
  </joint>

  <joint name="l_leg_kny" type="revolute">
    <origin xyz="-0.064105 0 -0.422097" />
    <parent link="l_uleg" />
    <child link="l_lleg" />
    <axis xyz="0 1 0" />
    <limit lower="0" upper="2.3561944901923" effort="150" velocity="1.6" />
    <dynamics damping="1.0" friction="0" />
  </joint>

  <joint name="r_leg_kny" type="revolute">
    <origin xyz="-0.064105 0 -0.422097" />
    <parent link="r_uleg" />
    <child link="r_lleg" />
    <axis xyz="0 1 0" />
    <limit lower="0" upper="2.3561944901923" effort="150" velocity="1.6" />
    <dynamics damping="1.0" friction="0" />
  </joint>

  <joint name="l_leg_aky" type="revolute">
    <origin xyz="0.049706 -0.035 -0.4190624" />
    <parent link="l_lleg" />
    <child link="l_foot" />
    <axis xyz="0 1 0" />
    <limit lower="-0.95993108859688" upper="0.61086523819802" effort="150" velocity="1.6" />
    <dynamics damping="1.0" friction="0" />
  </joint>

  <joint name="r_leg_aky" type="revolute">
    <origin xyz="0.049706 0.035 -0.4190624" />
    <parent link="r_lleg" />
    <child link="r_foot" />
    <axis xyz="0 1 0" />
    <limit lower="-0.95993108859688" upper="0.61086523819802" effort="150" velocity="1.6" />
    <dynamics damping="1.0" friction="0" />
  </joint>

</robot>


