<?xml version="1.0" ?>
<sdf version="1.4">
<model name="V2Exoskeleton">
  <static>false</static>

  <link name="torso">
    <pose>-0.0085 0 1.0180015 0 0 0</pose>
    <collision name="torso_collision">
      <geometry>
        <box>
          <size>0.25 0.3 0.3299971</size>
        </box>
      </geometry>
    </collision>
    <visual name="torso_visual">
      <pose>0 0 0 0 0 0</pose>
      <geometry>
        <box>
					<size>0.25 0.3 0.3299971</size>
				</box>
      </geometry>
    </visual>
    <inertial>
      <pose>-0.002953866 -2.8926e-05 0.014503041 0 0 0</pose>
      <mass>12.352637257467</mass>
      <inertia>
        <ixx>0.192434317</ixx>
        <iyy>0.138750791</iyy>
        <izz>0.152566986</izz>
        <iyz>6.1397e-05</iyz>
        <ixz>0.005354688</ixz>
        <ixy>0.000154048</ixy>
      </inertia>
    </inertial>
    <sensor name="imu_sensor" type="imu">
      <pose>0 0 0 0 0 1.5707963</pose>
      <always_on>1</always_on>
      <visualize>1</visualize>
      <topic>imu_sensor</topic>
    </sensor>
  </link>


  <link name="l_thigh">
    <pose>-0.002281 0.117675 0.6903315 0 0 0</pose>
    <collision name="l_thigh_collision">
      <geometry>
        <box>
          <size>0.1 0.18965 0.4496629</size>
        </box>
      </geometry>
    </collision>
    <visual name="l_thigh_visual">
      <pose>0 0 0 0 0 0</pose>
      <geometry>
        <box>
					<size>0.1 0.18965 0.4496629</size>
				</box>
      </geometry>
    </visual>
    <inertial>
      <pose>-0.007275145 0.001182411 -0.002326944 0 0 0</pose>
      <mass>7.1491717950398</mass>
      <inertia>
        <ixx>0.084250058</ixx>
        <iyy>0.096381201</iyy>
        <izz>0.045852856</izz>
        <iyz>-0.001798911</iyz>
        <ixz>-0.016761334</ixz>
        <ixy>-0.004359838</ixy>
      </inertia>
    </inertial>
  </link>

  <link name="r_thigh">
    <pose>-0.002281 -0.117675 0.6903315 0 0 0</pose>
    <collision name="r_thigh_collision">
      <geometry>
        <box>
          <size>0.1 0.18965 0.4496629</size>
        </box>
      </geometry>
    </collision>
    <visual name="r_thigh_visual">
      <pose>0 0 0 0 0 0</pose>
      <geometry>
        <box>
					<size>0.1 0.18965 0.4496629</size>
				</box>
      </geometry>
    </visual>
    <inertial>
      <pose>-0.011960341 -0.003014569 0.0026838300000001 0 0 0</pose>
      <mass>6.7392390451449</mass>
      <inertia>
        <ixx>0.079240154</ixx>
        <iyy>0.089456087</iyy>
        <izz>0.043072055</izz>
        <iyz>0.003245855</iyz>
        <ixz>-0.014283399</ixz>
        <ixy>-0.005800059</ixy>
      </inertia>
    </inertial>
  </link>


  <link name="l_shin">
    <pose>0.0190724 0.1021182 0.2811108 0 0 0</pose>
    <collision name="l_shin_collision">
      <geometry>
        <box>
          <size>0.1 0.13 0.4512008</size>
        </box>
      </geometry>
    </collision>
    <visual name="l_shin_visual">
      <pose>0 0 0 0 0 0</pose>
      <geometry>
        <box>
					<size>0.1 0.13 0.4512008</size>
				</box>
      </geometry>
    </visual>
    <inertial>
      <pose>0.020009023 -0.001720267 0.053753428 0 0 0</pose>
      <mass>4.5253558007679</mass>
      <inertia>
        <ixx>0.046092742</ixx>
        <iyy>0.047576074</iyy>
        <izz>0.017089465</izz>
        <iyz>-0.000398792</iyz>
        <ixz>0.007328075</ixz>
        <ixy>-5.375e-05</ixy>
      </inertia>
    </inertial>
  </link>

  <link name="r_shin">
    <pose>0.0190724 -0.1021182 0.2811108 0 0 0</pose>
    <collision name="r_shin_collision">
      <geometry>
        <box>
          <size>0.1 0.13 0.4512008</size>
        </box>
      </geometry>
    </collision>
    <visual name="r_shin_visual">
      <pose>0 0 0 0 0 0</pose>
      <geometry>
        <box>
					<size>0.1 0.13 0.4512008</size>
				</box>
      </geometry>
    </visual>
    <inertial>
      <pose>0.020008902 0.001800992 0.053753033 0 0 0</pose>
      <mass>4.5253557242616</mass>
      <inertia>
        <ixx>0.046093172</ixx>
        <iyy>0.047576244</iyy>
        <izz>0.017089664</izz>
        <iyz>0.000388378</iyz>
        <ixz>0.007328046</ixz>
        <ixy>7.7546e-05</ixy>
      </inertia>
    </inertial>
  </link>


  <link name="l_foot">
    <pose>0.025 0.1 0.0266724 0 0 0</pose>
    <collision name="l_foot_collision">
      <geometry>
        <box>
          <size>0.25 0.1485 0.05493235</size>
        </box>
      </geometry>
      <!-- From atlas model -->
      <surface>
        <friction>
          <ode>
            <mu>0.9</mu>
            <mu2>0.9</mu2>
            <fdir1>1 0 0</fdir1>
          </ode>
        </friction>
        <contact>
          <ode>
            <max_vel>1.0</max_vel>
            <min_depth>0.003</min_depth>
          </ode>
        </contact>
      </surface>
    </collision>
    <visual name="l_foot_visual">
      <pose>0 0 0 0 0 0</pose>
      <geometry>
        <box>
					<size>0.25 0.1485 0.05493235</size>
				</box>
      </geometry>
    </visual>
    <inertial>
      <pose>-0.028605608 0.000378564 0.010183651 0 0 0</pose>
      <mass>1.7554505521062</mass>
      <inertia>
        <ixx>0.003706824</ixx>
        <iyy>0.007284474</iyy>
        <izz>0.007592302</izz>
        <iyz>2.331e-05</iyz>
        <ixz>-0.001373646</ixz>
        <ixy>1.3207e-05</ixy>
      </inertia>
    </inertial>
    <sensor name="l_foot_contact_sensor" type="contact">
      <always_on>1</always_on>
      <contact>
        <collision>l_foot_collision</collision>
      </contact>
    </sensor>
  </link>

  <link name="r_foot">
    <pose>0.025 -0.1 0.0266724 0 0 0</pose>
    <collision name="r_foot_collision">
      <geometry>
        <box>
          <size>0.25 0.1485 0.05493235</size>
        </box>
      </geometry>
      <!-- From atlas model -->
      <surface>
        <friction>
          <ode>
            <mu>0.9</mu>
            <mu2>0.9</mu2>
            <fdir1>1 0 0</fdir1>
          </ode>
        </friction>
        <contact>
          <ode>
            <max_vel>1.0</max_vel>
            <min_depth>0.003</min_depth>
          </ode>
        </contact>
      </surface>
    </collision>
    <visual name="r_foot_visual">
      <pose>0 0 0 0 0 0</pose>
      <geometry>
        <box>
					<size>0.25 0.1485 0.05493235</size>
				</box>
      </geometry>
    </visual>
    <inertial>
      <pose>-0.028322076 -0.000365984 0.010187761 0 0 0</pose>
      <mass>1.7588867652665</mass>
      <inertia>
        <ixx>0.003363358</ixx>
        <iyy>0.006961913</iyy>
        <izz>0.007424205</izz>
        <iyz>-2.3263e-05</iyz>
        <ixz>-0.001368115</ixz>
        <ixy>-8.734e-06</ixy>
      </inertia>
    </inertial>
    <sensor name="r_foot_contact_sensor" type="contact">
      <always_on>1</always_on>
      <contact>
        <collision>r_foot_collision</collision>
      </contact>
    </sensor>
  </link>

  <joint name="l_hip_pitch" type="revolute">
    <pose>0.002281 -0.017675 0.2096685 0 0 0</pose>
    <parent>
      l_hip_pitch_trunnion
    </parent>
    <child>
      l_thigh
    </child>
    <axis>
      <xyz>0 1 0</xyz>
      <limit>
        <lower>-0.34906585039887</lower>
        <upper>0.78539816339745</upper>
        <effort>150</effort>
        <velocity>12</velocity>
      </limit>
      <dynamics>
        <damping>1.0</damping>
        <friction>0</friction>
      </dynamics>
    </axis>
    <physics>
      <ode>
        <cfm_damping>1</cfm_damping>
      </ode>
    </physics>
  </joint>

  <joint name="r_hip_pitch" type="revolute">
    <pose>0.002281 0.017675 0.2096685 0 0 0</pose>
    <parent>
      r_hip_pitch_trunnion
    </parent>
    <child>
      r_thigh
    </child>
    <axis>
      <xyz>0 1 0</xyz>
      <limit>
        <lower>-0.78539816339745</lower>
        <upper>0.34906585039887</upper>
        <effort>150</effort>
        <velocity>12</velocity>
      </limit>
      <dynamics>
        <damping>1.0</damping>
        <friction>0</friction>
      </dynamics>
    </axis>
    <physics>
      <ode>
        <cfm_damping>1</cfm_damping>
      </ode>
    </physics>
  </joint>

  <joint name="l_knee_pitch" type="revolute">
    <pose>-0.0190724 -0.0021182 0.2088892 0 0 0</pose>
    <parent>
      l_thigh
    </parent>
    <child>
      l_shin
    </child>
    <axis>
      <xyz>0 1 0</xyz>
      <limit>
        <lower>0</lower>
        <upper>2.3561944901923</upper>
        <effort>150</effort>
        <velocity>12</velocity>
      </limit>
      <dynamics>
        <damping>1.0</damping>
        <friction>0</friction>
      </dynamics>
    </axis>
    <physics>
      <ode>
        <cfm_damping>1</cfm_damping>
      </ode>
    </physics>
  </joint>

  <joint name="r_knee_pitch" type="revolute">
    <pose>-0.0190724 0.0021182 0.2088892 0 0 0</pose>
    <parent>
      r_thigh
    </parent>
    <child>
      r_shin
    </child>
    <axis>
      <xyz>0 1 0</xyz>
      <limit>
        <lower>0</lower>
        <upper>2.3561944901923</upper>
        <effort>150</effort>
        <velocity>12</velocity>
      </limit>
      <dynamics>
        <damping>1.0</damping>
        <friction>0</friction>
      </dynamics>
    </axis>
    <physics>
      <ode>
        <cfm_damping>1</cfm_damping>
      </ode>
    </physics>
  </joint>

  <joint name="l_ankle_pitch" type="revolute">
    <parent>
      l_shin
    </parent>
    <child>
      l_foot
    </child>
    <axis>
      <xyz>0 1 0</xyz>
      <limit>
        <lower>-0.95993108859688</lower>
        <upper>0.61086523819802</upper>
        <effort>150</effort>
        <velocity>12</velocity>
      </limit>
      <dynamics>
        <damping>1.0</damping>
        <friction>0</friction>
      </dynamics>
    </axis>
    <physics>
      <ode>
        <cfm_damping>1</cfm_damping>
      </ode>
    </physics>
  </joint>

  <joint name="r_ankle_pitch" type="revolute">
    <parent>
      r_shin
    </parent>
    <child>
      r_foot
    </child>
    <axis>
      <xyz>0 1 0</xyz>
      <limit>
        <lower>-0.95993108859688</lower>
        <upper>0.61086523819802</upper>
        <effort>150</effort>
        <velocity>12</velocity>
      </limit>
      <dynamics>
        <damping>1.0</damping>
        <friction>0</friction>
      </dynamics>
    </axis>
    <physics>
      <ode>
        <cfm_damping>1</cfm_damping>
      </ode>
    </physics>
  </joint>

</model>
</sdf>


