<?xml version="1.0"?>
<robot name="escher" xmlns:xacro="http://www.ros.org/wiki/xacro">

  <material name="$black">
    <color rgba="0 0 0 1.0"/>
  </material>

  <material name="$grey">
    <color rgba="0.15686274509804 0.15686274509804 0.15686274509804 1.0"/>
  </material>

  <material name="$silver">
    <color rgba="0.66274509803922 0.66274509803922 0.66274509803922 1.0"/>
  </material>

  <link name="base_link">
    <origin xyz="0 0 0.9" />
    <inertial>
      <mass value="0" />
      <inertia ixx="0" iyy="0" izz="0" ixy="0" ixz="0" iyz="0" />
    </inertial>
  </link>

  <link name="torso">
    <origin xyz="0 0 0.9" />
    <collision name="torso_collision">
      <origin xyz="-0.03035 0 0.155" />
      <geometry>
        <box size="0.307 0.41 0.26" />
      </geometry>
    </collision>
    <visual name="torso_visual">
      <origin xyz="-0.03035 0 0.155" />
      <geometry>
        <box size="0.307 0.41 0.26" />
      </geometry>
      <material name="$silver"/>
    </visual>
    <inertial>
      <origin xyz="-0.027546522 -8.1528e-05 0.133351888" />
      <mass value="12.682282372305" />
      <inertia ixx="0.189594996" iyy="0.165226373" izz="0.191129536" iyz="2.491e-05" ixz="-0.00084363" ixy="0.000243698" />
    </inertial>
  </link>

  <link name="kvh_link" />

  <joint name="kvh_joint" type="fixed">
    <origin xyz="-0.184 0 0.109355" rpy="0 0 1.5707963267949" />
    <axis xyz="0 0 1" />
    <parent link="torso" />
    <child link="kvh_link" />
  </joint>

  <link name="pelvis" />

  <joint name="pelvis_joint" type="fixed">
    <origin xyz="0 0 0" rpy="0 0 0" />
    <axis xyz="0 0 1" />
    <parent link="torso" />
    <child link="pelvis" />
  </joint>

  <link name="microstrain_link" />

  <joint name="microstrain_joint" type="fixed">
    <origin xyz="-0.206541689 0 0.099894166" rpy="0 0 0" />
    <axis xyz="0 0 1" />
    <parent link="torso" />
    <child link="microstrain_link" />
  </joint>

  <link name="l_thigh">
    <collision name="l_thigh_collision">
      <origin xyz="-0.0169442 0.032 -0.23" rpy="0 -0.15 0" />
      <geometry>
        <box size="0.28 0.21 0.45" />
      </geometry>
    </collision>
    <visual name="l_thigh_visual">
      <origin xyz="-0.0169442 0.032 -0.23" />
      <geometry>
        <box size="0.28 0.21 0.45" />
      </geometry>
      <material name="$silver"/>
    </visual>
    <inertial>
      <origin xyz="-0.012893801 0.021195329 -0.207094181" />
      <mass value="7.1174945701086" />
      <inertia ixx="0.079832533" iyy="0.090497961" izz="0.04397275" iyz="-0.003214845" ixz="-0.014464827" ixy="0.005608169" />
    </inertial>
  </link>

  <link name="r_thigh">
    <collision name="r_thigh_collision">
      <origin xyz="-0.0169442 -0.032 -0.23" rpy="0 -0.18 0" />
      <geometry>
        <box size="0.28 0.21 0.45" />
      </geometry>
    </collision>
    <visual name="r_thigh_visual">
      <origin xyz="-0.0169442 -0.032 -0.23" />
      <geometry>
        <box size="0.28 0.21 0.45" />
      </geometry>
      <material name="$silver"/>
    </visual>
    <inertial>
      <origin xyz="-0.013034539 -0.020824424 -0.207001063" />
      <mass value="7.1102215149036" />
      <inertia ixx="0.079523937" iyy="0.090222577" izz="0.044391657" iyz="0.003378144" ixz="-0.014386485" ixy="-0.005865006" />
    </inertial>
  </link>

  <link name="l_shin">
    <collision name="l_shin_collision">
      <origin xyz="0.0190724 0.0021182 -0.2088892" rpy="0 0.28 0" />
      <geometry>
        <box size="0.13 0.16 0.4512008" />
      </geometry>
    </collision>
    <visual name="l_shin_visual">
      <origin xyz="0.0190724 0.0021182 -0.2088892" />
      <geometry>
        <box size="0.13 0.16 0.4512008" />
      </geometry>
      <material name="$silver"/>
    </visual>
    <inertial>
      <origin xyz="0.039203201 0.000387055 -0.154164379" />
      <mass value="4.8991768711307" />
      <inertia ixx="0.049926224" iyy="0.051902624" izz="0.017996958" iyz="-0.000412746" ixz="0.008459786" ixy="-6.1882e-05" />
    </inertial>
  </link>

  <link name="r_shin">
    <collision name="r_shin_collision">
      <origin xyz="0.0190724 -0.0021182 -0.2088892" rpy="0 0.28 0" />
      <geometry>
        <box size="0.13 0.16 0.4512008" />
      </geometry>
    </collision>
    <visual name="r_shin_visual">
      <origin xyz="0.0190724 -0.0021182 -0.2088892" />
      <geometry>
        <box size="0.13 0.16 0.4512008" />
      </geometry>
      <material name="$silver"/>
    </visual>
    <inertial>
      <origin xyz="0.039203093 -0.000281832 -0.15416472" />
      <mass value="4.899176790308" />
      <inertia ixx="0.049926754" iyy="0.051902784" izz="0.01799724" iyz="0.000377725" ixz="0.008459765" ixy="8.0717e-05" />
    </inertial>
  </link>


  <link name="l_foot">
    <collision name="l_foot_collision">
      <origin xyz="0.025 0 -0.053276" />
      <geometry>
        <box size="0.25 0.1485 0.05493235" />
      </geometry>
    </collision>
    <visual name="l_foot_visual">
      <origin xyz="0.025 0 -0.053276" />
      <geometry>
        <box size="0.25 0.1485 0.05493235" />
      </geometry>
      <material name="$silver"/>
    </visual>
    <inertial>
      <origin xyz="-0.003540497 0.00037102999999999 -0.043693482" />
      <mass value="1.8008403819182" />
      <inertia ixx="0.003629189" iyy="0.007181627" izz="0.007515445" iyz="2.3132e-05" ixz="-0.001366256" ixy="1.3079e-05" />
    </inertial>
  </link>

  <link name="r_foot">
    <collision name="r_foot_collision">
      <origin xyz="0.025 0 -0.0533276" />
      <geometry>
        <box size="0.25 0.1485 0.05493235" />
      </geometry>
    </collision>
    <visual name="r_foot_visual">
      <origin xyz="0.025 0 -0.0533276" />
      <geometry>
        <box size="0.25 0.1485 0.05493235" />
      </geometry>
      <material name="$silver"/>
    </visual>
    <inertial>
      <origin xyz="-0.003252817 -0.00035825099999999 -0.043692447" />
      <mass value="1.8047217702742" />
      <inertia ixx="0.003638673" iyy="0.007191304" izz="0.007526564" iyz="-2.3098e-05" ixz="-0.001360529" ixy="8.912e-06" />
    </inertial>
  </link>

  <link name="l_sole"/>

  <link name="r_sole"/>

  <joint name="l_sole_joint" type="fixed">
    <origin xyz="0.025 0 -0.08" />
    <parent link="l_foot"/>
    <child link="l_sole"/>
  </joint>

  <joint name="r_sole_joint" type="fixed">
    <origin xyz="0.025 0 -0.08" />
    <parent link="r_foot"/>
    <child link="r_sole"/>
  </joint>

  <link name="l_hip_yaw_trunnion">
    <!-- Axis = "z", -->
    <inertial>
      <mass value="0.051809443030815" />
      <inertia ixx="0.0085833333333333" iyy="0.0085833333333333" izz="0.00075" ixy="0" ixz="0" iyz="0" />
    </inertial>
  </link>

  <link name="r_hip_yaw_trunnion">
    <!-- Axis = "z", -->
    <inertial>
      <mass value="0.051809443030815" />
      <inertia ixx="0.0085833333333333" iyy="0.0085833333333333" izz="0.00075" ixy="0" ixz="0" iyz="0" />
    </inertial>
  </link>


  <link name="l_hip_pitch_trunnion">
    <!-- Axis = "y", -->
    <inertial>
      <origin rpy="1.5707963267949 0 0" />
      <mass value="0.051809443030815" />
      <inertia ixx="0.0085833333333333" iyy="0.0085833333333333" izz="0.00075" ixy="0" ixz="0" iyz="0" />
    </inertial>
  </link>

  <link name="r_hip_pitch_trunnion">
    <!-- Axis = "y", -->
    <inertial>
      <origin rpy="1.5707963267949 0 0" />
      <mass value="0.051809443030815" />
      <inertia ixx="0.0085833333333333" iyy="0.0085833333333333" izz="0.00075" ixy="0" ixz="0" iyz="0" />
    </inertial>
  </link>


  <link name="l_ankle_pitch_trunnion">
    <!-- Axis = "y", -->
    <inertial>
      <origin rpy="1.5707963267949 0 0" />
      <mass value="0.051809443030815" />
      <inertia ixx="0.0085833333333333" iyy="0.0085833333333333" izz="0.00075" ixy="0" ixz="0" iyz="0" />
    </inertial>
  </link>

  <link name="r_ankle_pitch_trunnion">
    <!-- Axis = "y", -->
    <inertial>
      <origin rpy="1.5707963267949 0 0" />
      <mass value="0.051809443030815" />
      <inertia ixx="0.0085833333333333" iyy="0.0085833333333333" izz="0.00075" ixy="0" ixz="0" iyz="0" />
    </inertial>
  </link>

  <joint name="base_joint" type="fixed">
    <origin xyz="0 0 0" rpy="0 0 0" />
    <axis xyz="0 0 1"/>
    <parent link="base_link" />
    <child link="torso" />
  </joint>

  <joint name="l_hip_yaw" type="revolute">
    <origin xyz="0 0.1 0" />
    <parent link="torso" />
    <child link="l_hip_yaw_trunnion" />
    <axis xyz="0 0 1" />
    <limit lower="-0.34906585039887" upper="0.78539816339745" effort="150" velocity="1.6" />
    <dynamics damping="1.0" friction="0" />
  </joint>

  <joint name="r_hip_yaw" type="revolute">
    <origin xyz="0 -0.1 0" />
    <parent link="torso" />
    <child link="r_hip_yaw_trunnion" />
    <axis xyz="0 0 1" />
    <limit lower="-0.78539816339745" upper="0.34906585039887" effort="150" velocity="1.6" />
    <dynamics damping="1.0" friction="0" />
  </joint>

  <joint name="l_hip_roll" type="revolute">
    <origin xyz="0 0 0" />
    <parent link="l_hip_yaw_trunnion" />
    <child link="l_hip_pitch_trunnion" />
    <axis xyz="1 0 0" />
    <limit lower="-0.5235987755983" upper="0.78539816339745" effort="150" velocity="1.6" />
    <dynamics damping="1.0" friction="0" />
  </joint>

  <joint name="r_hip_roll" type="revolute">
    <origin xyz="0 0 0" />
    <parent link="r_hip_yaw_trunnion" />
    <child link="r_hip_pitch_trunnion" />
    <axis xyz="1 0 0" />
    <limit lower="-0.78539816339745" upper="0.5235987755983" effort="150" velocity="1.6" />
    <dynamics damping="1.0" friction="0" />
  </joint>

  <joint name="l_hip_pitch" type="revolute">
    <origin xyz="0 0 0" />
    <parent link="l_hip_pitch_trunnion" />
    <child link="l_thigh" />
    <axis xyz="0 1 0" />
    <limit lower="-2.0943951023932" upper="0.5235987755983" effort="150" velocity="1.6" />
    <dynamics damping="1.0" friction="0" />
  </joint>

  <joint name="r_hip_pitch" type="revolute">
    <origin xyz="0 0 0" />
    <parent link="r_hip_pitch_trunnion" />
    <child link="r_thigh" />
    <axis xyz="0 1 0" />
    <limit lower="-2.0943951023932" upper="0.5235987755983" effort="150" velocity="1.6" />
    <dynamics damping="1.0" friction="0" />
  </joint>

  <joint name="l_knee_pitch" type="revolute">
    <origin xyz="0 0 -0.41" />
    <parent link="l_thigh" />
    <child link="l_shin" />
    <axis xyz="0 1 0" />
    <limit lower="0" upper="2.3561944901923" effort="150" velocity="1.6" />
    <dynamics damping="1.0" friction="0" />
  </joint>

  <joint name="r_knee_pitch" type="revolute">
    <origin xyz="0 0 -0.41" />
    <parent link="r_thigh" />
    <child link="r_shin" />
    <axis xyz="0 1 0" />
    <limit lower="0" upper="2.3561944901923" effort="150" velocity="1.6" />
    <dynamics damping="1.0" friction="0" />
  </joint>

  <joint name="l_ankle_pitch" type="revolute">
    <origin xyz="0 0 -0.41" />
    <parent link="l_shin" />
    <child link="l_ankle_pitch_trunnion" />
    <axis xyz="0 1 0" />
    <limit lower="-0.95993108859688" upper="0.61086523819802" effort="150" velocity="1.6" />
    <dynamics damping="1.0" friction="0" />
  </joint>

  <joint name="r_ankle_pitch" type="revolute">
    <origin xyz="0 0 -0.41" />
    <parent link="r_shin" />
    <child link="r_ankle_pitch_trunnion" />
    <axis xyz="0 1 0" />
    <limit lower="-0.95993108859688" upper="0.61086523819802" effort="150" velocity="1.6" />
    <dynamics damping="1.0" friction="0" />
  </joint>

  <joint name="l_ankle_roll" type="revolute">
    <origin xyz="0 0 0" />
    <parent link="l_ankle_pitch_trunnion" />
    <child link="l_foot" />
    <axis xyz="1 0 0" />
    <limit lower="-0.5235987755983" upper="0.5235987755983" effort="150" velocity="1.6" />
    <dynamics damping="1.0" friction="0" />
  </joint>

  <joint name="r_ankle_roll" type="revolute">
    <origin xyz="0 0 0" />
    <parent link="r_ankle_pitch_trunnion" />
    <child link="r_foot" />
    <axis xyz="1 0 0" />
    <limit lower="-0.5235987755983" upper="0.5235987755983" effort="150" velocity="1.6" />
    <dynamics damping="1.0" friction="0" />
  </joint>

  <joint name="waist_yaw" type="revolute">
    <origin xyz="0 0 0.273" />
    <parent link="torso" />
    <child link="chest" />
    <axis xyz="0 0 1" />
    <limit lower="-0.78539816339745" upper="0.78539816339745" effort="150" velocity="1.6" />
    <dynamics damping="1.0" friction="0" />
  </joint>

  <link name="chest">
    <collision name="chest_collision">
      <origin xyz="-0.02515 0 0.1725" />
      <geometry>
        <box size="0.24 0.43 0.325" />
      </geometry>
    </collision>
    <collision name="chest_collision_2">
      <origin xyz="0 0.139 0.485" />
      <geometry>
        <box size="0.1 0.08 0.33" />
      </geometry>
    </collision>
    <collision name="chest_collision_3">
      <origin xyz="0 -0.139 0.485" />
      <geometry>
        <box size="0.1 0.08 0.33" />
      </geometry>
    </collision>
    <collision name="chest_collision_4">
      <origin xyz="0 0 0.652" />
      <geometry>
        <box size="0.05 0.22 0.045" />
      </geometry>
    </collision>
    <visual name="chest_visual">
      <origin xyz="-0.02515 0 0.1725" />
      <geometry>
        <box size="0.24 0.43 0.325" />
      </geometry>
      <material name="$silver"/>
    </visual>
    <inertial>
      <origin xyz="-0.024651386 -0.000572102 0.17357052" />
      <mass value="15.99243891983" />
      <inertia ixx="0.320061097" iyy="0.258881187" izz="0.19263458" iyz="0.005595512" ixz="-0.006857708" ixy="-0.001679142" />
    </inertial>
  </link>

  <link name="utorso" />

  <joint name="utorso_joint" type="fixed">
    <origin xyz="0 0 0" rpy="0 0 0" />
    <axis xyz="0 0 1" />
    <parent link="chest" />
    <child link="utorso" />
  </joint>

  <joint name="head_yaw" type="revolute">
    <origin xyz="0 0 0.365" />
    <parent link="chest" />
    <child link="neck" />
    <axis xyz="0 0 1" />
    <limit lower="-1.5707963267949" upper="1.5707963267949" effort="150" velocity="1.6" />
    <dynamics damping="1.0" friction="0" />
  </joint>

  <link name="neck">
    <collision name="neck_collision">
      <origin xyz="0 0.003 0.021525" />
      <geometry>
        <box size="0.0541 0.096 0.05405" />
      </geometry>
    </collision>
    <visual name="neck_visual">
      <origin xyz="0 0.003 0.021525" />
      <geometry>
        <box size="0.0541 0.096 0.05405" />
      </geometry>
      <material name="$silver"/>
    </visual>
    <inertial>
      <origin xyz="-1e-08 0.000288781 0.025711325" />
      <mass value="0.44370991981621" />
      <inertia ixx="0.000347468" iyy="0.000151286" izz="0.000333572" iyz="-8.157e-06" ixz="-0" ixy="0" />
    </inertial>
  </link>

  <joint name="head_pitch" type="revolute">
    <origin xyz="0 0 0.0286" />
    <parent link="neck" />
    <child link="head" />
    <axis xyz="0 1 0" />
    <limit lower="-0.5235987755983" upper="1.0471975511966" effort="150" velocity="1.6" />
    <dynamics damping="1.0" friction="0" />
  </joint>

  <link name="head">
    <collision name="head_collision">
      <origin xyz="-0.0142568 0 0.07445" />
      <geometry>
        <box size="0.155386 0.122 0.2991" />
      </geometry>
    </collision>
    <visual name="head_visual">
      <origin xyz="-0.0142568 0 0.07445" />
      <geometry>
        <box size="0.155386 0.122 0.2991" />
      </geometry>
      <material name="$grey"/>
    </visual>
    <inertial>
      <origin xyz="-0.019043518 1.1808e-05 0.138525812" />
      <mass value="1.788406731087" />
      <inertia ixx="0.009989911" iyy="0.010295295" izz="0.003904584" iyz="-8.541e-06" ixz="0.002192988" ixy="3.49e-06" />
    </inertial>
  </link>

  <!-- MultiSense stereo camera -->

  <gazebo reference="left_camera_frame">
    <sensor type="multicamera" name="stereo_camera">
      <!-- see MultiSenseSLPlugin.h for available modes -->
      <update_rate>30.0</update_rate>
      <camera name="left">
        <!-- Spec sheet says 80deg X 45deg @ 1024x544pix.  Based on feedback
             from teams, we're instead doing 80deg X 80deg @ 800x800pix. -->
        <horizontal_fov>1.3962634</horizontal_fov>
        <image>
          <width>800</width>
          <height>800</height>
          <format>R8G8B8</format>
        </image>
        <clip>
          <near>0.02</near>
          <far>300</far>
        </clip>
        <noise>
          <type>gaussian</type>
          <mean>0.0</mean>
          <stddev>0.007</stddev>
        </noise>
      </camera>
      <camera name="right">
        <pose>0 -0.07 0 0 0 0</pose>
        <!-- Spec sheet says 80deg X 45deg @ 1024x544pix.  Based on feedback
             from teams, we're instead doing 80deg X 80deg @ 800x800pix. -->
        <horizontal_fov>1.3962634</horizontal_fov>
        <image>
          <width>800</width>
          <height>800</height>
          <format>R8G8B8</format>
        </image>
        <clip>
          <near>0.02</near>
          <far>300</far>
        </clip>
        <noise>
          <type>gaussian</type>
          <!-- Noise is sampled independently per pixel on each frame.
               That pixel's noise value is added to each of its color
               channels, which at that point lie in the range [0,1].
               The stddev value of 0.007 is based on experimental data
               from a camera in a Sandia hand pointed at a static scene
               in a couple of different lighting conditions.  -->
          <mean>0.0</mean>
          <stddev>0.007</stddev>
        </noise>
      </camera>
      <plugin name="stereo_camera_controller" filename="libgazebo_ros_multicamera.so">
        <alwaysOn>true</alwaysOn>
        <updateRate>0.0</updateRate>
        <cameraName>multisense</cameraName>
        <imageTopicName>image_color</imageTopicName>
        <cameraInfoTopicName>camera_info</cameraInfoTopicName>
        <frameName>/multisense/left_camera_optical_frame</frameName>
        <!--<rightFrameName>/multisense/right_camera_optical_frame</rightFrameName>-->
        <hackBaseline>0.07</hackBaseline>
        <distortionK1>0.0</distortionK1>
        <distortionK2>0.0</distortionK2>
        <distortionK3>0.0</distortionK3>
        <distortionT1>0.0</distortionT1>
        <distortionT2>0.0</distortionT2>
      </plugin>
    </sensor>
  </gazebo>

  <!-- Multisense params Imported from Official Multisense URDF -->
  <link name="multisense_root"/>

  <joint name="multisense_joint" type="fixed">
    <origin xyz="-0.000435 0 0.18627" />
    <parent link="head"/>
    <child link="multisense_root"/>
  </joint>

  <joint name="left_camera_joint" type="fixed">
    <origin xyz="0.052 0.035 0.0"/>
    <parent link="multisense_root"/>
    <child link="left_camera_frame"/>
  </joint>

  <link name="left_camera_frame"/>

  <joint name="right_camera_joint" type="fixed">
    <origin xyz="0.052 -0.035 0.0"/>
    <parent link="multisense_root"/>
    <child link="right_camera_frame"/>
  </joint>

  <link name="right_camera_frame"/>

  <joint name="left_camera_optical_joint" type="fixed">
    <origin xyz="0 0 0" rpy="-1.57079632679 0.0 -1.57079632679"/>
    <parent link="left_camera_frame"/>
    <child link="/multisense/left_camera_optical_frame"/>
  </joint>

  <link name="/multisense/left_camera_optical_frame"/>

  <joint name="right_camera_optical_joint" type="fixed">
    <origin xyz="0 0 0" rpy="-1.57079632679 0.0 -1.57079632679"/>
    <parent link="right_camera_frame"/>
    <child link="/multisense/right_camera_optical_frame"/>
  </joint>

  <link name="/multisense/right_camera_optical_frame"/>

  <joint name="accel_joint" type="fixed">
    <origin xyz="0.047 0.0302 -0.00075" rpy="0.0 1.57079632679 0.0"/>
    <parent link="multisense_root"/>
    <child link="accel"/>
  </joint>

  <link name="accel"/>

  <joint name="mag_joint" type="fixed">
    <origin xyz="0.047 0.0302 -0.00075" rpy="0.0 1.57079632679 0.0"/>
    <parent link="multisense_root"/>
    <child link="mag"/>
  </joint>

  <link name="mag"/>

  <joint name="gyro_joint" type="fixed">
    <origin xyz="0.047 0.03880 0.00125" rpy="-1.57079632679 0.0 -1.57079632679"/>
    <parent link="multisense_root"/>
    <child link="gyro"/>
  </joint>

  <link name="gyro"/>

  <!-- Head Lidar -->
  <joint name="head_lidar_roll" type="continuous">
    <origin xyz="0 0 0.089" />
    <parent link="head" />
    <child link="head_lidar" />
    <axis xyz="1 0 0" />
    <limit effort="150" velocity="1.6"/>
    <dynamics damping="1.0" friction="0" />
  </joint>

  <link name="head_lidar">
    <collision name="head_lidar_collision">
      <origin xyz="0 0 0" />
      <geometry>
        <box size="0.1395 0.06 0.093" />
      </geometry>
    </collision>
    <visual name="head_lidar_visual">
      <origin xyz="0.0098 0 0" />
      <geometry>
        <box size="0.1395 0.06 0.093" />
      </geometry>
      <material name="$black"/>
    </visual>
    <inertial>
      <origin xyz="0.025363303 -2.21e-06 -3.303568776" />
      <mass value="0.44979898625387" />
      <inertia ixx="0.000368817" iyy="0.000869352" izz="0.000701866" iyz="-2.1e-08" ixz="-8.417e-06" ixy="5.5e-08" />
    </inertial>
  </link>

  <joint name="head_lidar_emitter_joint" type="fixed">
    <origin xyz="0.0495 0 0.02" />
    <parent link="head_lidar" />
    <child link="head_lidar_emitter" />
  </joint>

  <link name="head_hokuyo_frame" />

  <joint name="head_hokuyo_frame_joint" type="fixed">
    <origin xyz="0 0 0" rpy="0 0 0" />
    <axis xyz="0 0 1" />
    <parent link="head_lidar" />
    <child link="head_hokuyo_frame" />
  </joint>

  <link name="head_lidar_emitter"/>

  <joint name="head_lidar_receiver_joint" type="fixed">
    <origin xyz="0.0495 0 0.0115" />
    <parent link="head_lidar" />
    <child link="head_lidar_receiver" />
  </joint>

  <link name="head_lidar_receiver"/>

  <joint name="head_lidar_empirical_joint" type="fixed">
    <origin xyz="0 -0.0075 0.0065" />
    <parent link="head_lidar_emitter" />
    <child link="head_lidar_empirical" />
  </joint>

  <link name="head_lidar_empirical" />

  <!-- hdt arms -->
  <xacro:include filename="$(find hdt_7dof_description)/urdf/hdt_7dof_macro_bbox.xacro" />
  <xacro:hdt_7dof_left parent="chest" x="0" y="0.1275" z="0.2804" prefix="l_" motor_base_id="41" />
  <xacro:hdt_7dof_right parent="chest" x="0" y="-0.1275" z="0.2804" prefix="r_" motor_base_id="1" />
</robot>


